Workbook

Sheet LISTA
A1: CODIGO | B1: NRO ORIGINAL | C1: DESCRIPCION | D1: MARCA | E1: COSTO USD | F1: MARGEN | G1: PRECIO VENTA USD | H1: PRECIO VENTA BS | I1: PRECIO VENTA COP | J1: CANTIDAD_TOTAL
A2: SK1301A | C2: ABRAZADERA BARRA ESTABILIZADORA R-18/FUEGO | E2: 1.75 | F2: 0.3 | G2: =ROUND(E2*(1+F2),2) -> 2.28 | H2: =ROUND(G2*NOTAS!$B$2,2) -> 1644.67 | I2: =ROUND(G2*NOTAS!$B$3,0) -> 7407 | J2: 1
A3: 06-5A-14467 | C3: ABRAZADERA BARRA ESTABILIZADORA R-18/FUEGO | D3: SANFOR | E3: 1.75 | F3: 0.3 | G3: =ROUND(E3*(1+F3),2) -> 2.28 | H3: =ROUND(G3*NOTAS!$B$2,2) -> 1644.67 | I3: =ROUND(G3*NOTAS!$B$3,0) -> 7407 | J3: 1
C4: ABRAZADERA CENTRAL BARRA ESTABILIZADORA R-11/19 | E4: 1.75 | F4: 0.3 | G4: =ROUND(E4*(1+F4),2) -> 2.28 | H4: =ROUND(G4*NOTAS!$B$2,2) -> 1644.67 | I4: =ROUND(G4*NOTAS!$B$3,0) -> 7407 | J4: 4
A5: 12479 | C5: ABRAZADERA PUNTA BARRA ESTABILIZADORA R-11/19 | E5: 1.75 | F5: 0.3 | G5: =ROUND(E5*(1+F5),2) -> 2.28 | H5: =ROUND(G5*NOTAS!$B$2,2) -> 1644.67 | I5: =ROUND(G5*NOTAS!$B$3,0) -> 7407 | J5: 3
A6: SAE 25W-60 | C6: ACEITE CASTROL GTX | D6: CASTROL | E6: 14.6154 | F6: 0.3 | G6: =ROUND(E6*(1+F6),2) -> 19 | H6: =ROUND(G6*NOTAS!$B$2,2) -> 13705.57 | I6: =ROUND(G6*NOTAS!$B$3,0) -> 61729 | J6: 18
C7: ACOPLE CAJA DIRECCION CIELO | D7: KOREA | E7: 9.6154 | F7: 0.3 | G7: =ROUND(E7*(1+F7),2) -> 12.5 | H7: =ROUND(G7*NOTAS!$B$2,2) -> 9016.82 | I7: =ROUND(G7*NOTAS!$B$3,0) -> 40611 | J7: 4
C8: ACOPLE CAJA DIRECCION R-12 | D8: SANFOR | E8: 10 | F8: 0.3 | G8: =ROUND(E8*(1+F8),2) -> 13 | H8: =ROUND(G8*NOTAS!$B$2,2) -> 9377.49 | I8: =ROUND(G8*NOTAS!$B$3,0) -> 42235 | J8: 3
C9: ALFOMBRAS NEGRA CHEVROLET | D9: ZEGA | E9: 47.6923 | F9: 0.3 | G9: =ROUND(E9*(1+F9),2) -> 62 | H9: =ROUND(G9*NOTAS!$B$2,2) -> 44723.43 | I9: =ROUND(G9*NOTAS!$B$3,0) -> 201430 | J9: 1
C10: ALFOMBRAS NEGRA FIAT | D10: ZEGA | E10: 47.6923 | F10: 0.3 | G10: =ROUND(E10*(1+F10),2) -> 62 | H10: =ROUND(G10*NOTAS!$B$2,2) -> 44723.43 | I10: =ROUND(G10*NOTAS!$B$3,0) -> 201430 | J10: 1
C11: ALFOMBRAS NEGRA FORD | D11: ZEGA | E11: 46.1538 | F11: 0.3 | G11: =ROUND(E11*(1+F11),2) -> 60 | H11: =ROUND(G11*NOTAS!$B$2,2) -> 43280.74 | I11: =ROUND(G11*NOTAS!$B$3,0) -> 194932 | J11: 2
A12: 96314258 | C12: ALTERNADOR MATIZ POLEA SIMPLE EN V | D12: MIRE | E12: 57.6923 | F12: 0.3 | G12: =ROUND(E12*(1+F12),2) -> 75 | H12: =ROUND(G12*NOTAS!$B$2,2) -> 54100.92 | I12: =ROUND(G12*NOTAS!$B$3,0) -> 243665 | J12: 1
A13: GP30064..Y | C13: AMORTIGUADOR DELANTERO CORSA | D13: COFAP | E13: 25 | F13: 0.3 | G13: =ROUND(E13*(1+F13),2) -> 32.5 | H13: =ROUND(G13*NOTAS!$B$2,2) -> 23443.73 | I13: =ROUND(G13*NOTAS!$B$3,0) -> 105588 | J13: 1
A14: MP8148 | C14: AMORTIGUADOR DELANTERO CORSA | D14: BOGE | E14: 25 | F14: 0.3 | G14: =ROUND(E14*(1+F14),2) -> 32.5 | H14: =ROUND(G14*NOTAS!$B$2,2) -> 23443.73 | I14: =ROUND(G14*NOTAS!$B$3,0) -> 105588 | J14: 4
A15: MP8297 | C15: AMORTIGUADOR DELANTERO ECOSPORT | D15: BOGE | E15: 25 | F15: 0.3 | G15: =ROUND(E15*(1+F15),2) -> 32.5 | H15: =ROUND(G15*NOTAS!$B$2,2) -> 23443.73 | I15: =ROUND(G15*NOTAS!$B$3,0) -> 105588 | J15: 1
A16: 4337G | C16: AMORTIGUADOR DELANTERO R-TWINGO | D16: SACHS | E16: 25 | F16: 0.3 | G16: =ROUND(E16*(1+F16),2) -> 32.5 | H16: =ROUND(G16*NOTAS!$B$2,2) -> 23443.73 | I16: =ROUND(G16*NOTAS!$B$3,0) -> 105588 | J16: 1
A17: 902112 | B17: 2S65A406A10AE | C17: AMORTIGUADOR MALETA FIESTA 04/13 | D17: FORD | E17: 15 | F17: 0.3 | G17: =ROUND(E17*(1+F17),2) -> 19.5 | H17: =ROUND(G17*NOTAS!$B$2,2) -> 14066.24 | I17: =ROUND(G17*NOTAS!$B$3,0) -> 63353 | J17: 2
A18: DR.16030 C.Y | C18: AMORTIGUADOR MALETA F-UNO | D18: COFAP | E18: 10 | F18: 0.3 | G18: =ROUND(E18*(1+F18),2) -> 13 | H18: =ROUND(G18*NOTAS!$B$2,2) -> 9377.49 | I18: =ROUND(G18*NOTAS!$B$3,0) -> 42235 | J18: 10
A19: GB47798..Y | C19: AMORTIGUADOR TRASERO CORSA | D19: COFAP | E19: 15 | F19: 0.3 | G19: =ROUND(E19*(1+F19),2) -> 19.5 | H19: =ROUND(G19*NOTAS!$B$2,2) -> 14066.24 | I19: =ROUND(G19*NOTAS!$B$3,0) -> 63353 | J19: 5
A20: 832387 | C20: AMORTIGUADOR TRASERO ECOSPORT | D20: BOGE | E20: 15 | F20: 0.3 | G20: =ROUND(E20*(1+F20),2) -> 19.5 | H20: =ROUND(G20*NOTAS!$B$2,2) -> 14066.24 | I20: =ROUND(G20*NOTAS!$B$3,0) -> 63353 | J20: 6
A21: 832386 | C21: AMORTIGUADOR TRASERO FIESTA 04/13 | D21: BOGE | E21: 15 | F21: 0.3 | G21: =ROUND(E21*(1+F21),2) -> 19.5 | H21: =ROUND(G21*NOTAS!$B$2,2) -> 14066.24 | I21: =ROUND(G21*NOTAS!$B$3,0) -> 63353 | J21: 2
A22: 93740225 STD | C22: ANILLOS MOTOR AVEO 1.6 STD | D22: DAEWOO | E22: 20 | F22: 0.3 | G22: =ROUND(E22*(1+F22),2) -> 26 | H22: =ROUND(G22*NOTAS!$B$2,2) -> 18754.99 | I22: =ROUND(G22*NOTAS!$B$3,0) -> 84471 | J22: 1
A23: DA.6689 050 | C23: ANILLOS MOTOR CHEVETTE 1.6 81,98MM 050 F/F | D23: COFAP | E23: 20 | F23: 0.3 | G23: =ROUND(E23*(1+F23),2) -> 26 | H23: =ROUND(G23*NOTAS!$B$2,2) -> 18754.99 | I23: =ROUND(G23*NOTAS!$B$3,0) -> 84471 | J23: 3
A24: DA.6404 050 | C24: ANILLOS MOTOR CHEVETTE 1.6 81,98MM 050 F/G | D24: COFAP | E24: 20 | F24: 0.3 | G24: =ROUND(E24*(1+F24),2) -> 26 | H24: =ROUND(G24*NOTAS!$B$2,2) -> 18754.99 | I24: =ROUND(G24*NOTAS!$B$3,0) -> 84471 | J24: 10
A25: DA.6404 075 | C25: ANILLOS MOTOR CHEVETTE 1.6 81,98MM 075 F/G | D25: COFAP | E25: 20 | F25: 0.3 | G25: =ROUND(E25*(1+F25),2) -> 26 | H25: =ROUND(G25*NOTAS!$B$2,2) -> 18754.99 | I25: =ROUND(G25*NOTAS!$B$3,0) -> 84471 | J25: 8
A26: DA.6689 100 | C26: ANILLOS MOTOR CHEVETTE 1.6 81,98MM 100 F/F | D26: COFAP | E26: 20 | F26: 0.3 | G26: =ROUND(E26*(1+F26),2) -> 26 | H26: =ROUND(G26*NOTAS!$B$2,2) -> 18754.99 | I26: =ROUND(G26*NOTAS!$B$3,0) -> 84471 | J26: 1
A27: DA.6404 100 | C27: ANILLOS MOTOR CHEVETTE 1.6 81,98MM 100 F/G | D27: COFAP | E27: 20 | F27: 0.3 | G27: =ROUND(E27*(1+F27),2) -> 26 | H27: =ROUND(G27*NOTAS!$B$2,2) -> 18754.99 | I27: =ROUND(G27*NOTAS!$B$3,0) -> 84471 | J27: 3
A28: DA.6404 STD | C28: ANILLOS MOTOR CHEVETTE 1.6 81,98MM STD F/G | D28: COFAP | E28: 20 | F28: 0.3 | G28: =ROUND(E28*(1+F28),2) -> 26 | H28: =ROUND(G28*NOTAS!$B$2,2) -> 18754.99 | I28: =ROUND(G28*NOTAS!$B$3,0) -> 84471 | J28: 5
A29: CA.4990 STD | C29: ANILLOS MOTOR CHEVETTE 1.6 82MM STD G/G | D29: COFAP | E29: 20 | F29: 0.3 | G29: =ROUND(E29*(1+F29),2) -> 26 | H29: =ROUND(G29*NOTAS!$B$2,2) -> 18754.99 | I29: =ROUND(G29*NOTAS!$B$3,0) -> 84471 | J29: 0
... A98: 4218003 | C98: ANTENA TECHO CORSA 2PTAS | D98: BRITE | E98: 6.1538 | F98: 0.3 | G98: =ROUND(E98*(1+F98),2) -> 8 | H98: =ROUND(G98*NOTAS!$B$2,2) -> 5770.76 | I98: =ROUND(G98*NOTAS!$B$3,0) -> 25991 | J98: 1
C99: ANTENA TECHO CORSA 2PTAS | D99: NSN | E99: 6.1538 | F99: 0.3 | G99: =ROUND(E99*(1+F99),2) -> 8 | H99: =ROUND(G99*NOTAS!$B$2,2) -> 5770.76 | I99: =ROUND(G99*NOTAS!$B$3,0) -> 25991 | J99: 1
A100: 11093042 | C100: ARANDELA BOMBA ACEITE CIELO/LANOS/CORSA | D100: GM | E100: 2.3077 | F100: 0.3 | G100: =ROUND(E100*(1+F100),2) -> 3 | H100: =ROUND(G100*NOTAS!$B$2,2) -> 2164.04 | I100: =ROUND(G100*NOTAS!$B$3,0) -> 9747 | J100: 20
A101: 266 | C101: ARBOL DE LEVA CHEVETTE 1.6 | D101: APLIC | E101: 70 | F101: 0.3 | G101: =ROUND(E101*(1+F101),2) -> 91 | H101: =ROUND(G101*NOTAS!$B$2,2) -> 65642.45 | I101: =ROUND(G101*NOTAS!$B$3,0) -> 295647 | J101: 4
A102: 133 | C102: ARBOL DE LEVA CORCEL | D102: APLIC | E102: 26 | F102: 0.3 | G102: =ROUND(E102*(1+F102),2) -> 33.8 | H102: =ROUND(G102*NOTAS!$B$2,2) -> 24381.48 | I102: =ROUND(G102*NOTAS!$B$3,0) -> 109812 | J102: 1
A103: 312 | C103: ARBOL DE LEVA F-147/UNO 1.3 | D103: APLIC | E103: 70 | F103: 0.3 | G103: =ROUND(E103*(1+F103),2) -> 91 | H103: =ROUND(G103*NOTAS!$B$2,2) -> 65642.45 | I103: =ROUND(G103*NOTAS!$B$3,0) -> 295647 | J103: 2
A104: 900108 | C104: ARBOL DE LEVA FIESTA/KA 1.6 OXIDADO | D104: FORD | E104: 70 | F104: 0.3 | G104: =ROUND(E104*(1+F104),2) -> 91 | H104: =ROUND(G104*NOTAS!$B$2,2) -> 65642.45 | I104: =ROUND(G104*NOTAS!$B$3,0) -> 295647 | J104: 2
A105: 339 | C105: ARBOL DE LEVA F-PALIO/SIENA 1.3 16V FIRE ADMICION | D105: APLIC | E105: 72 | F105: 0.3 | G105: =ROUND(E105*(1+F105),2) -> 93.6 | H105: =ROUND(G105*NOTAS!$B$2,2) -> 67517.95 | I105: =ROUND(G105*NOTAS!$B$3,0) -> 304094 | J105: 2
A106: 320 | C106: ARBOL DE LEVA F-PALIO/SIENA 1.3 8V MPI | D106: APLIC | E106: 70 | F106: 0.3 | G106: =ROUND(E106*(1+F106),2) -> 91 | H106: =ROUND(G106*NOTAS!$B$2,2) -> 65642.45 | I106: =ROUND(G106*NOTAS!$B$3,0) -> 295647 | J106: 2
A107: 93235615-1 | C107: ARBOL DE LEVA F-PALIO/SIENA 1.8 IDEA | D107: ZUTACA | E107: 50 | F107: 0.3 | G107: =ROUND(E107*(1+F107),2) -> 65 | H107: =ROUND(G107*NOTAS!$B$2,2) -> 46887.46 | I107: =ROUND(G107*NOTAS!$B$3,0) -> 211177 | J107: 1
A108: 267 | C108: ARBOL DE LEVA MONZA | D108: APLIC | E108: 70 | F108: 0.3 | G108: =ROUND(E108*(1+F108),2) -> 91 | H108: =ROUND(G108*NOTAS!$B$2,2) -> 65642.45 | I108: =ROUND(G108*NOTAS!$B$3,0) -> 295647 | J108: 3
...

Sheet NOTAS
A1: PARÁMETROS DE CONVERSIÓN — editar las celdas amarillas recalcula toda la lista
A2: Tasa Bs/USD (BCV) | B2: 721.3456 | C2: Banco Central de Venezuela, tipo de cambio de referencia del 13-07-2026 (bcv.org.ve via bcv.today)
A3: Tasa COP/USD (TRM) | B3: 3248.87 | C3: TRM oficial Colombia vigente desde el 11-07-2026, Superfinanciera (datos.gov.co)
A5: COSTO USD: dato original del archivo (la columna decía Bs pero estaba en dólares).
A6: MARGEN: margen de venta fijo del 30%, el mismo aplicado en data/raw_ventas.xlsx.
A7: PRECIO VENTA USD = COSTO USD × (1+MARGEN); BS y COP se calculan con las tasas de arriba.
